[2023-03-29T18:44:05.455+0000] {taskinstance.py:1165} INFO - Dependencies all met for <TaskInstance: user_processing.process_user manual__2023-03-29T18:44:00.987028+00:00 [queued]>
[2023-03-29T18:44:05.462+0000] {taskinstance.py:1165} INFO - Dependencies all met for <TaskInstance: user_processing.process_user manual__2023-03-29T18:44:00.987028+00:00 [queued]>
[2023-03-29T18:44:05.464+0000] {taskinstance.py:1362} INFO - 
--------------------------------------------------------------------------------
[2023-03-29T18:44:05.465+0000] {taskinstance.py:1363} INFO - Starting attempt 1 of 1
[2023-03-29T18:44:05.466+0000] {taskinstance.py:1364} INFO - 
--------------------------------------------------------------------------------
[2023-03-29T18:44:05.473+0000] {taskinstance.py:1383} INFO - Executing <Task(PythonOperator): process_user> on 2023-03-29 18:44:00.987028+00:00
[2023-03-29T18:44:05.479+0000] {standard_task_runner.py:55} INFO - Started process 17279 to run task
[2023-03-29T18:44:05.482+0000] {standard_task_runner.py:82} INFO - Running: ['***', 'tasks', 'run', 'user_processing', 'process_user', 'manual__2023-03-29T18:44:00.987028+00:00', '--job-id', '16', '--raw', '--subdir', 'DAGS_FOLDER/user_processing.py', '--cfg-path', '/tmp/tmpdg2wrk1p']
[2023-03-29T18:44:05.484+0000] {standard_task_runner.py:83} INFO - Job 16: Subtask process_user
[2023-03-29T18:44:05.530+0000] {task_command.py:376} INFO - Running <TaskInstance: user_processing.process_user manual__2023-03-29T18:44:00.987028+00:00 [running]> on host 9dcb783b1f3a
[2023-03-29T18:44:05.569+0000] {taskinstance.py:1592} INFO - Exporting the following env vars:
AIRFLOW_CTX_DAG_OWNER=***
AIRFLOW_CTX_DAG_ID=user_processing
AIRFLOW_CTX_TASK_ID=process_user
AIRFLOW_CTX_EXECUTION_DATE=2023-03-29T18:44:00.987028+00:00
AIRFLOW_CTX_TRY_NUMBER=1
AIRFLOW_CTX_DAG_RUN_ID=manual__2023-03-29T18:44:00.987028+00:00
[2023-03-29T18:44:05.583+0000] {taskinstance.py:1851} ERROR - Task failed with exception
Traceback (most recent call last):
  File "/home/airflow/.local/lib/python3.7/site-packages/airflow/operators/python.py", line 175, in execute
    return_value = self.execute_callable()
  File "/home/airflow/.local/lib/python3.7/site-packages/airflow/operators/python.py", line 193, in execute_callable
    return self.python_callable(*self.op_args, **self.op_kwargs)
  File "/opt/airflow/dags/user_processing.py", line 23, in _process_user_
    processed_user.to_csv('tmp/processed_user.csv',header=False,index=None)
  File "/home/airflow/.local/lib/python3.7/site-packages/pandas/core/generic.py", line 3482, in to_csv
    storage_options=storage_options,
  File "/home/airflow/.local/lib/python3.7/site-packages/pandas/io/formats/format.py", line 1105, in to_csv
    csv_formatter.save()
  File "/home/airflow/.local/lib/python3.7/site-packages/pandas/io/formats/csvs.py", line 243, in save
    storage_options=self.storage_options,
  File "/home/airflow/.local/lib/python3.7/site-packages/pandas/io/common.py", line 707, in get_handle
    newline="",
FileNotFoundError: [Errno 2] No such file or directory: 'tmp/processed_user.csv'
[2023-03-29T18:44:05.594+0000] {taskinstance.py:1406} INFO - Marking task as FAILED. dag_id=user_processing, task_id=process_user, execution_date=20230329T184400, start_date=20230329T184405, end_date=20230329T184405
[2023-03-29T18:44:05.602+0000] {standard_task_runner.py:105} ERROR - Failed to execute job 16 for task process_user ([Errno 2] No such file or directory: 'tmp/processed_user.csv'; 17279)
[2023-03-29T18:44:05.615+0000] {local_task_job.py:164} INFO - Task exited with return code 1
[2023-03-29T18:44:05.636+0000] {local_task_job.py:273} INFO - 0 downstream tasks scheduled from follow-on schedule check
